{
  "nbformat": 4,
  "nbformat_minor": 0,
  "metadata": {
    "colab": {
      "name": "keras_retinanet.ipynb",
      "version": "0.3.2",
      "provenance": []
    },
    "kernelspec": {
      "name": "python3",
      "display_name": "Python 3"
    },
    "accelerator": "GPU"
  },
  "cells": [
    {
      "metadata": {
        "id": "I-Bl_AwErBX3",
        "colab_type": "code",
        "outputId": "cd2afa23-14ae-4e4b-b6cc-0c691404284a",
        "colab": {
          "base_uri": "https://localhost:8080/",
          "height": 34
        }
      },
      "cell_type": "code",
      "source": [
        "from google.colab import drive\n",
        "drive.mount('/content/gdrive')"
      ],
      "execution_count": 0,
      "outputs": [
        {
          "output_type": "stream",
          "text": [
            "Drive already mounted at /content/gdrive; to attempt to forcibly remount, call drive.mount(\"/content/gdrive\", force_remount=True).\n"
          ],
          "name": "stdout"
        }
      ]
    },
    {
      "metadata": {
        "id": "duoQOnHBrYay",
        "colab_type": "code",
        "outputId": "babe7137-40a3-490a-bc55-07a060627911",
        "colab": {
          "base_uri": "https://localhost:8080/",
          "height": 51
        }
      },
      "cell_type": "code",
      "source": [
        "!git clone https://github.com/fizyr/keras-retinanet.git"
      ],
      "execution_count": 0,
      "outputs": [
        {
          "output_type": "stream",
          "text": [
            "shell-init: error retrieving current directory: getcwd: cannot access parent directories: No such file or directory\n",
            "fatal: could not create work tree dir 'keras-retinanet': No such file or directory\n"
          ],
          "name": "stdout"
        }
      ]
    },
    {
      "metadata": {
        "id": "FxVp-xKhrN7w",
        "colab_type": "code",
        "outputId": "00a459dd-5a82-4358-93d1-3d87afa0766e",
        "colab": {
          "base_uri": "https://localhost:8080/",
          "height": 894
        }
      },
      "cell_type": "code",
      "source": [
        "%cd keras-retinanet/\n",
        "\n",
        "!pip install ."
      ],
      "execution_count": 0,
      "outputs": [
        {
          "output_type": "stream",
          "text": [
            "ERROR:root:Internal Python error in the inspect module.\n",
            "Below is the traceback from this internal error.\n",
            "\n"
          ],
          "name": "stderr"
        },
        {
          "output_type": "stream",
          "text": [
            "Traceback (most recent call last):\n",
            "  File \"/usr/local/lib/python3.6/dist-packages/IPython/core/interactiveshell.py\", line 2882, in run_code\n",
            "    exec(code_obj, self.user_global_ns, self.user_ns)\n",
            "  File \"<ipython-input-20-98f9add72cbe>\", line 1, in <module>\n",
            "    get_ipython().magic('cd keras-retinanet/')\n",
            "  File \"/usr/local/lib/python3.6/dist-packages/IPython/core/interactiveshell.py\", line 2160, in magic\n",
            "    return self.run_line_magic(magic_name, magic_arg_s)\n",
            "  File \"/usr/local/lib/python3.6/dist-packages/IPython/core/interactiveshell.py\", line 2081, in run_line_magic\n",
            "    result = fn(*args,**kwargs)\n",
            "  File \"</usr/local/lib/python3.6/dist-packages/decorator.py:decorator-gen-91>\", line 2, in cd\n",
            "  File \"/usr/local/lib/python3.6/dist-packages/IPython/core/magic.py\", line 188, in <lambda>\n",
            "    call = lambda f, *a, **k: f(*a, **k)\n",
            "  File \"/usr/local/lib/python3.6/dist-packages/IPython/core/magics/osm.py\", line 288, in cd\n",
            "    oldcwd = py3compat.getcwd()\n",
            "FileNotFoundError: [Errno 2] No such file or directory\n",
            "\n",
            "During handling of the above exception, another exception occurred:\n",
            "\n",
            "Traceback (most recent call last):\n",
            "  File \"/usr/local/lib/python3.6/dist-packages/IPython/core/interactiveshell.py\", line 1823, in showtraceback\n",
            "    stb = value._render_traceback_()\n",
            "AttributeError: 'FileNotFoundError' object has no attribute '_render_traceback_'\n",
            "\n",
            "During handling of the above exception, another exception occurred:\n",
            "\n",
            "Traceback (most recent call last):\n",
            "  File \"/usr/local/lib/python3.6/dist-packages/IPython/core/ultratb.py\", line 1132, in get_records\n",
            "    return _fixed_getinnerframes(etb, number_of_lines_of_context, tb_offset)\n",
            "  File \"/usr/local/lib/python3.6/dist-packages/IPython/core/ultratb.py\", line 313, in wrapped\n",
            "    return f(*args, **kwargs)\n",
            "  File \"/usr/local/lib/python3.6/dist-packages/IPython/core/ultratb.py\", line 358, in _fixed_getinnerframes\n",
            "    records = fix_frame_records_filenames(inspect.getinnerframes(etb, context))\n",
            "  File \"/usr/lib/python3.6/inspect.py\", line 1488, in getinnerframes\n",
            "    frameinfo = (tb.tb_frame,) + getframeinfo(tb, context)\n",
            "  File \"/usr/lib/python3.6/inspect.py\", line 1446, in getframeinfo\n",
            "    filename = getsourcefile(frame) or getfile(frame)\n",
            "  File \"/usr/lib/python3.6/inspect.py\", line 696, in getsourcefile\n",
            "    if getattr(getmodule(object, filename), '__loader__', None) is not None:\n",
            "  File \"/usr/lib/python3.6/inspect.py\", line 725, in getmodule\n",
            "    file = getabsfile(object, _filename)\n",
            "  File \"/usr/lib/python3.6/inspect.py\", line 709, in getabsfile\n",
            "    return os.path.normcase(os.path.abspath(_filename))\n",
            "  File \"/usr/lib/python3.6/posixpath.py\", line 376, in abspath\n",
            "    cwd = os.getcwd()\n",
            "FileNotFoundError: [Errno 2] No such file or directory\n"
          ],
          "name": "stdout"
        },
        {
          "output_type": "error",
          "ename": "FileNotFoundError",
          "evalue": "ignored",
          "traceback": [
            "\u001b[0;31m---------------------------------------------------------------------------\u001b[0m"
          ]
        }
      ]
    },
    {
      "metadata": {
        "id": "2LmbQaKAr9k_",
        "colab_type": "code",
        "outputId": "38d8b56c-6895-4970-c84d-8339908ff74c",
        "colab": {
          "base_uri": "https://localhost:8080/",
          "height": 68
        }
      },
      "cell_type": "code",
      "source": [
        "!python setup.py build_ext --inplace"
      ],
      "execution_count": 0,
      "outputs": [
        {
          "output_type": "stream",
          "text": [
            "shell-init: error retrieving current directory: getcwd: cannot access parent directories: No such file or directory\n",
            "shell-init: error retrieving current directory: getcwd: cannot access parent directories: No such file or directory\n",
            "python3: can't open file 'setup.py': [Errno 2] No such file or directory\n"
          ],
          "name": "stdout"
        }
      ]
    },
    {
      "metadata": {
        "id": "r-77hjqItCbP",
        "colab_type": "code",
        "colab": {}
      },
      "cell_type": "code",
      "source": [
        "import os\n",
        "import shutil\n",
        "import zipfile\n",
        "import urllib\n",
        "import xml.etree.ElementTree as ET\n",
        "import numpy as np\n",
        "import csv\n",
        "import pandas\n",
        "from google.colab import drive\n",
        "from google.colab import files"
      ],
      "execution_count": 0,
      "outputs": []
    },
    {
      "metadata": {
        "id": "PD8ZNAJdtRjy",
        "colab_type": "code",
        "colab": {}
      },
      "cell_type": "code",
      "source": [
        "DATASET_DRIVEID = '1YgTANSod7X5Yf-3YvsrbJPSwvESxq2b2'\n",
        "DATASET_DIR = 'dataset'\n",
        "ANNOTATIONS_FILE = 'annotations.csv'\n",
        "CLASSES_FILE = 'classes.csv'"
      ],
      "execution_count": 0,
      "outputs": []
    },
    {
      "metadata": {
        "id": "rd3HGv-9tYhf",
        "colab_type": "code",
        "outputId": "502afe69-319f-490f-c62d-f345e0fe0da3",
        "colab": {
          "base_uri": "https://localhost:8080/",
          "height": 775
        }
      },
      "cell_type": "code",
      "source": [
        "drive_url = 'https://drive.google.com/uc?export=download&id=' + DATASET_DRIVEID\n",
        "file_name = DATASET_DRIVEID + '.zip'\n",
        "\n",
        "urllib.request.urlretrieve(drive_url, file_name)\n",
        "print('Download completed!')\n",
        "\n",
        "os.makedirs(DATASET_DIR, exist_ok=True)\n",
        "with zipfile.ZipFile(file_name, 'r') as zip_ref:\n",
        "  zip_ref.extractall(DATASET_DIR)\n",
        "os.remove(file_name)\n",
        "print('Extract completed!')"
      ],
      "execution_count": 0,
      "outputs": [
        {
          "output_type": "stream",
          "text": [
            "ERROR:root:Internal Python error in the inspect module.\n",
            "Below is the traceback from this internal error.\n",
            "\n"
          ],
          "name": "stderr"
        },
        {
          "output_type": "stream",
          "text": [
            "Traceback (most recent call last):\n",
            "  File \"/usr/local/lib/python3.6/dist-packages/IPython/core/interactiveshell.py\", line 2882, in run_code\n",
            "    exec(code_obj, self.user_global_ns, self.user_ns)\n",
            "  File \"<ipython-input-17-b8affac741c8>\", line 4, in <module>\n",
            "    urllib.request.urlretrieve(drive_url, file_name)\n",
            "  File \"/usr/lib/python3.6/urllib/request.py\", line 258, in urlretrieve\n",
            "    tfp = open(filename, 'wb')\n",
            "FileNotFoundError: [Errno 2] No such file or directory: '1YgTANSod7X5Yf-3YvsrbJPSwvESxq2b2.zip'\n",
            "\n",
            "During handling of the above exception, another exception occurred:\n",
            "\n",
            "Traceback (most recent call last):\n",
            "  File \"/usr/local/lib/python3.6/dist-packages/IPython/core/interactiveshell.py\", line 1823, in showtraceback\n",
            "    stb = value._render_traceback_()\n",
            "AttributeError: 'FileNotFoundError' object has no attribute '_render_traceback_'\n",
            "\n",
            "During handling of the above exception, another exception occurred:\n",
            "\n",
            "Traceback (most recent call last):\n",
            "  File \"/usr/local/lib/python3.6/dist-packages/IPython/core/ultratb.py\", line 1132, in get_records\n",
            "    return _fixed_getinnerframes(etb, number_of_lines_of_context, tb_offset)\n",
            "  File \"/usr/local/lib/python3.6/dist-packages/IPython/core/ultratb.py\", line 313, in wrapped\n",
            "    return f(*args, **kwargs)\n",
            "  File \"/usr/local/lib/python3.6/dist-packages/IPython/core/ultratb.py\", line 358, in _fixed_getinnerframes\n",
            "    records = fix_frame_records_filenames(inspect.getinnerframes(etb, context))\n",
            "  File \"/usr/lib/python3.6/inspect.py\", line 1488, in getinnerframes\n",
            "    frameinfo = (tb.tb_frame,) + getframeinfo(tb, context)\n",
            "  File \"/usr/lib/python3.6/inspect.py\", line 1446, in getframeinfo\n",
            "    filename = getsourcefile(frame) or getfile(frame)\n",
            "  File \"/usr/lib/python3.6/inspect.py\", line 696, in getsourcefile\n",
            "    if getattr(getmodule(object, filename), '__loader__', None) is not None:\n",
            "  File \"/usr/lib/python3.6/inspect.py\", line 725, in getmodule\n",
            "    file = getabsfile(object, _filename)\n",
            "  File \"/usr/lib/python3.6/inspect.py\", line 709, in getabsfile\n",
            "    return os.path.normcase(os.path.abspath(_filename))\n",
            "  File \"/usr/lib/python3.6/posixpath.py\", line 376, in abspath\n",
            "    cwd = os.getcwd()\n",
            "FileNotFoundError: [Errno 2] No such file or directory\n"
          ],
          "name": "stdout"
        },
        {
          "output_type": "error",
          "ename": "FileNotFoundError",
          "evalue": "ignored",
          "traceback": [
            "\u001b[0;31m---------------------------------------------------------------------------\u001b[0m"
          ]
        }
      ]
    },
    {
      "metadata": {
        "id": "9z-aMUZxta-f",
        "colab_type": "code",
        "colab": {}
      },
      "cell_type": "code",
      "source": [
        "annotations = []\n",
        "classes = set([])\n",
        "\n",
        "for xml_file in [f for f in os.listdir(DATASET_DIR) if f.endswith(\".xml\")]:\n",
        "  tree = ET.parse(os.path.join(DATASET_DIR, xml_file))\n",
        "  root = tree.getroot()\n",
        "\n",
        "  file_name = None\n",
        "\n",
        "  for elem in root:\n",
        "    if elem.tag == 'filename':\n",
        "      file_name = os.path.join(DATASET_DIR, elem.text)\n",
        "\n",
        "    if elem.tag == 'object':\n",
        "      obj_name = None\n",
        "      coords = []\n",
        "      for subelem in elem:\n",
        "        if subelem.tag == 'name':\n",
        "          obj_name = subelem.text\n",
        "        if subelem.tag == 'bndbox':\n",
        "          for subsubelem in subelem:\n",
        "            coords.append(subsubelem.text)\n",
        "      item = [file_name] + coords + [obj_name]\n",
        "      annotations.append(item)\n",
        "      classes.add(obj_name)\n",
        "\n",
        "with open(ANNOTATIONS_FILE, 'w') as f:\n",
        "  writer = csv.writer(f)\n",
        "  writer.writerows(annotations)\n",
        "\n",
        "with open(CLASSES_FILE, 'w') as f:\n",
        "  for i, line in enumerate(classes):\n",
        "    f.write('{},{}\\n'.format(line,i))"
      ],
      "execution_count": 0,
      "outputs": []
    },
    {
      "metadata": {
        "id": "goSe3dyetffv",
        "colab_type": "code",
        "outputId": "b48bb86e-771c-4bb4-fe68-31348e9a9a3e",
        "colab": {
          "base_uri": "https://localhost:8080/",
          "height": 775
        }
      },
      "cell_type": "code",
      "source": [
        "PRETRAINED_MODEL = './snapshots/_pretrained_model.h5'\n",
        "\n",
        "#### OPTION 1: DOWNLOAD INITIAL PRETRAINED MODEL FROM FIZYR ####\n",
        "URL_MODEL = 'https://github.com/fizyr/keras-retinanet/releases/download/0.5.0/resnet50_coco_best_v2.1.0.h5'\n",
        "urllib.request.urlretrieve(URL_MODEL, PRETRAINED_MODEL)\n",
        "\n",
        "#### OPTION 2: DOWNLOAD CUSTOM PRETRAINED MODEL FROM GOOGLE DRIVE. CHANGE DRIVE_MODEL VALUE. USE THIS TO CONTINUE PREVIOUS TRAINING EPOCHS ####\n",
        "#drive.mount('/content/gdrive')\n",
        "#DRIVE_MODEL = '/content/gdrive/My Drive/Colab Notebooks/objdet_tensorflow_colab/resnet50_csv_10.h5'\n",
        "#shutil.copy(DRIVE_MODEL, PRETRAINED_MODEL)\n",
        "\n",
        "\n",
        "print('Downloaded pretrained model to ' + PRETRAINED_MODEL)"
      ],
      "execution_count": 0,
      "outputs": [
        {
          "output_type": "stream",
          "text": [
            "ERROR:root:Internal Python error in the inspect module.\n",
            "Below is the traceback from this internal error.\n",
            "\n"
          ],
          "name": "stderr"
        },
        {
          "output_type": "stream",
          "text": [
            "Traceback (most recent call last):\n",
            "  File \"/usr/local/lib/python3.6/dist-packages/IPython/core/interactiveshell.py\", line 2882, in run_code\n",
            "    exec(code_obj, self.user_global_ns, self.user_ns)\n",
            "  File \"<ipython-input-14-d0ecfb93766f>\", line 5, in <module>\n",
            "    urllib.request.urlretrieve(URL_MODEL, PRETRAINED_MODEL)\n",
            "  File \"/usr/lib/python3.6/urllib/request.py\", line 258, in urlretrieve\n",
            "    tfp = open(filename, 'wb')\n",
            "FileNotFoundError: [Errno 2] No such file or directory: './snapshots/_pretrained_model.h5'\n",
            "\n",
            "During handling of the above exception, another exception occurred:\n",
            "\n",
            "Traceback (most recent call last):\n",
            "  File \"/usr/local/lib/python3.6/dist-packages/IPython/core/interactiveshell.py\", line 1823, in showtraceback\n",
            "    stb = value._render_traceback_()\n",
            "AttributeError: 'FileNotFoundError' object has no attribute '_render_traceback_'\n",
            "\n",
            "During handling of the above exception, another exception occurred:\n",
            "\n",
            "Traceback (most recent call last):\n",
            "  File \"/usr/local/lib/python3.6/dist-packages/IPython/core/ultratb.py\", line 1132, in get_records\n",
            "    return _fixed_getinnerframes(etb, number_of_lines_of_context, tb_offset)\n",
            "  File \"/usr/local/lib/python3.6/dist-packages/IPython/core/ultratb.py\", line 313, in wrapped\n",
            "    return f(*args, **kwargs)\n",
            "  File \"/usr/local/lib/python3.6/dist-packages/IPython/core/ultratb.py\", line 358, in _fixed_getinnerframes\n",
            "    records = fix_frame_records_filenames(inspect.getinnerframes(etb, context))\n",
            "  File \"/usr/lib/python3.6/inspect.py\", line 1488, in getinnerframes\n",
            "    frameinfo = (tb.tb_frame,) + getframeinfo(tb, context)\n",
            "  File \"/usr/lib/python3.6/inspect.py\", line 1446, in getframeinfo\n",
            "    filename = getsourcefile(frame) or getfile(frame)\n",
            "  File \"/usr/lib/python3.6/inspect.py\", line 696, in getsourcefile\n",
            "    if getattr(getmodule(object, filename), '__loader__', None) is not None:\n",
            "  File \"/usr/lib/python3.6/inspect.py\", line 725, in getmodule\n",
            "    file = getabsfile(object, _filename)\n",
            "  File \"/usr/lib/python3.6/inspect.py\", line 709, in getabsfile\n",
            "    return os.path.normcase(os.path.abspath(_filename))\n",
            "  File \"/usr/lib/python3.6/posixpath.py\", line 376, in abspath\n",
            "    cwd = os.getcwd()\n",
            "FileNotFoundError: [Errno 2] No such file or directory\n"
          ],
          "name": "stdout"
        },
        {
          "output_type": "error",
          "ename": "FileNotFoundError",
          "evalue": "ignored",
          "traceback": [
            "\u001b[0;31m---------------------------------------------------------------------------\u001b[0m"
          ]
        }
      ]
    },
    {
      "metadata": {
        "id": "QO7Mc1kstmjg",
        "colab_type": "code",
        "outputId": "8b8e0e8c-81e2-4e72-b5e2-0b2a8c5901c0",
        "colab": {
          "base_uri": "https://localhost:8080/",
          "height": 649
        }
      },
      "cell_type": "code",
      "source": [
        "!keras_retinanet/bin/train.py --freeze-backbone --random-transform --weights {PRETRAINED_MODEL} --batch-size 8 --steps 100 --epochs 3 csv train.csv train_classes.csv"
      ],
      "execution_count": 0,
      "outputs": [
        {
          "output_type": "stream",
          "text": [
            "Using TensorFlow backend.\n",
            "2019-04-16 06:10:13.173277: I tensorflow/core/platform/profile_utils/cpu_utils.cc:94] CPU Frequency: 2300000000 Hz\n",
            "2019-04-16 06:10:13.173499: I tensorflow/compiler/xla/service/service.cc:150] XLA service 0x16751e0 executing computations on platform Host. Devices:\n",
            "2019-04-16 06:10:13.173530: I tensorflow/compiler/xla/service/service.cc:158]   StreamExecutor device (0): <undefined>, <undefined>\n",
            "2019-04-16 06:10:13.338137: I tensorflow/stream_executor/cuda/cuda_gpu_executor.cc:998] successful NUMA node read from SysFS had negative value (-1), but there must be at least one NUMA node, so returning NUMA node zero\n",
            "2019-04-16 06:10:13.338668: I tensorflow/compiler/xla/service/service.cc:150] XLA service 0x1674dc0 executing computations on platform CUDA. Devices:\n",
            "2019-04-16 06:10:13.338701: I tensorflow/compiler/xla/service/service.cc:158]   StreamExecutor device (0): Tesla T4, Compute Capability 7.5\n",
            "2019-04-16 06:10:13.339029: I tensorflow/core/common_runtime/gpu/gpu_device.cc:1433] Found device 0 with properties: \n",
            "name: Tesla T4 major: 7 minor: 5 memoryClockRate(GHz): 1.59\n",
            "pciBusID: 0000:00:04.0\n",
            "totalMemory: 14.73GiB freeMemory: 14.60GiB\n",
            "2019-04-16 06:10:13.339052: I tensorflow/core/common_runtime/gpu/gpu_device.cc:1512] Adding visible gpu devices: 0\n",
            "2019-04-16 06:10:13.782553: I tensorflow/core/common_runtime/gpu/gpu_device.cc:984] Device interconnect StreamExecutor with strength 1 edge matrix:\n",
            "2019-04-16 06:10:13.782631: I tensorflow/core/common_runtime/gpu/gpu_device.cc:990]      0 \n",
            "2019-04-16 06:10:13.782645: I tensorflow/core/common_runtime/gpu/gpu_device.cc:1003] 0:   N \n",
            "2019-04-16 06:10:13.782942: I tensorflow/core/common_runtime/gpu/gpu_device.cc:1115] Created TensorFlow device (/job:localhost/replica:0/task:0/device:GPU:0 with 14115 MB memory) -> physical GPU (device: 0, name: Tesla T4, pci bus id: 0000:00:04.0, compute capability: 7.5)\n",
            "Traceback (most recent call last):\n",
            "  File \"keras_retinanet/bin/train.py\", line 514, in <module>\n",
            "    main()\n",
            "  File \"keras_retinanet/bin/train.py\", line 444, in main\n",
            "    train_generator, validation_generator = create_generators(args, backbone.preprocess_image)\n",
            "  File \"keras_retinanet/bin/train.py\", line 276, in create_generators\n",
            "    **common_args\n",
            "  File \"keras_retinanet/bin/../../keras_retinanet/preprocessing/csv_generator.py\", line 160, in __init__\n",
            "    super(CSVGenerator, self).__init__(**kwargs)\n",
            "  File \"keras_retinanet/bin/../../keras_retinanet/preprocessing/generator.py\", line 84, in __init__\n",
            "    self.group_images()\n",
            "  File \"keras_retinanet/bin/../../keras_retinanet/preprocessing/generator.py\", line 253, in group_images\n",
            "    order.sort(key=lambda x: self.image_aspect_ratio(x))\n",
            "  File \"keras_retinanet/bin/../../keras_retinanet/preprocessing/generator.py\", line 253, in <lambda>\n",
            "    order.sort(key=lambda x: self.image_aspect_ratio(x))\n",
            "  File \"keras_retinanet/bin/../../keras_retinanet/preprocessing/csv_generator.py\", line 201, in image_aspect_ratio\n",
            "    image = Image.open(self.image_path(image_index))\n",
            "  File \"/usr/local/lib/python3.6/dist-packages/PIL/Image.py\", line 2530, in open\n",
            "    fp = builtins.open(filename, \"rb\")\n",
            "FileNotFoundError: [Errno 2] No such file or directory: 'train/1980.png'\n"
          ],
          "name": "stdout"
        }
      ]
    },
    {
      "metadata": {
        "id": "yJ3vPAh5ttOv",
        "colab_type": "code",
        "colab": {}
      },
      "cell_type": "code",
      "source": [
        ""
      ],
      "execution_count": 0,
      "outputs": []
    }
  ]
}